12:08:34 PM: DEBUG [persona.py:52] 
        ID: 1, Nombre: Joan, 
        Apellido: Herrera, Correo: Joanherrera@gmail.com
        
12:35:43 PM: DEBUG [persona.py:52] 
        ID: 1, Nombre: Joan, 
        Apellido: Herrera, Correo: Joanherrera@gmail.com
        
12:35:43 PM: DEBUG [persona.py:55] 
        ID: None, Nombre: Alexis, 
        Apellido: Vilte, Correo: Alexisvilte@gmail.com
        
12:36:54 PM: DEBUG [persona.py:52] 
        ID: 1, Nombre: Joan, 
        Apellido: Herrera, Correo: Joanherrera@gmail.com
        
12:36:54 PM: DEBUG [persona.py:55] 
        ID: None, Nombre: Alexis, 
        Apellido: Vilte, Correo: Alexisvilte@gmail.com
        
01:47:48 PM: ERROR [conexion.py:28] Ocurrio una excepcion al obtener la conexion invalid dsn: invalid connection option "dbport"

01:48:58 PM: ERROR [conexion.py:28] Ocurrio una excepcion al obtener la conexion invalid dsn: invalid connection option "dbport"

01:49:37 PM: ERROR [conexion.py:28] Ocurrio una excepcion al obtener la conexion invalid dsn: invalid connection option "dbport"

02:43:41 PM: ERROR [conexion.py:28] Ocurrio una excepcion al obtener la conexion connection to server at "localhost" (127.0.0.1), port 5432 failed: FATAL:  database "testdb" does not exist

02:44:12 PM: ERROR [conexion.py:28] Ocurrio una excepcion al obtener la conexion connection to server at "localhost" (127.0.0.1), port 5432 failed: FATAL:  database "testdb" does not exist

02:44:30 PM: DEBUG [conexion.py:25] Conexion exitosa <connection object at 0x7f1a61cb03d0; dsn: 'user=postgres password=xxx dbname=postgres host=localhost port=5432', closed: 0>
